const ApiError = require('../exceptions/api-error')

module.exports = function(err, req, res, next) {
	console.log(err)
	if (err instanceof ApiError) {
		return res.status(err.status).json({ message: err.message, errors: err.errors })
	}
	return res.status(500).json({ message: 'Непредвиденная ошибка' })
}

// передавать err будем, например, в catch(e): next(e)
